Workbook

Sheet Dashboard
A1: Studio Lotus — Operating Dashboard
A2: Live view of people, teams and software entitlements
A3: ="Last refreshed: " & TEXT(TODAY(),"dddd, mmmm d, yyyy") -> Last refreshed: Tuesday, June 2, 2026
A5: ⌂ Organisation
B7: Active Employees | C7: Principals | D7: Active Teams | E7: Interns | F7: Permanent | G7: Licensed People
B8: =COUNTIF(Master_Employees!P:P,TRUE()) -> 104 | C8: =4 -> 4 | D8: =COUNTIF(Groups!H:H,TRUE()) -> 17 | E8: =COUNTIFS(Master_Employees!O:O,"Intern",Master_Employees!P:P,TRUE()) -> 6 | F8: =COUNTIFS(Master_Employees!O:O,"Permanent",Master_Employees!P:P,TRUE()) -> 98 | G8: =SUMPRODUCT((Master_Employees!Q2:Q1000>0)*1) -> 87
B9: Include in Org = TRUE | C9: Harsh · Ambrish · Ankur · Asha | D9: across the studio | E9: currently on roll | F9: currently on roll | G9: have at least one tool
A11: ⌬ Licenses
B13: Software Titles | C13: Total Licenses | D13: License Assigned | E13: Spare Licenses | F13: Expiring 30d | G13: Expired
B14: =SUMPRODUCT((License_Inventory!C2:C194<>"")/COUNTIF(License_Inventory!C2:C194,License_Inventory!C2:C194&"")) -> 11 | C14: =SUM(License_Inventory!H:H) -> 297 | D14: =COUNTA(Licenses!A2:A4996) -> 216 | E14: =COUNTIFS(License_Inventory!O$2:O$199,">="&0,License_Inventory!O$2:O$199,"<="&30) -> 2 | F14: =COUNTIFS(License_Inventory!O$2:O$199,"<"&0) -> 0
B15: distinct tools | C15: across all contracts | D15: live assignments | E15: seats unallocated | F15: plan renewal | G15: renew now
A17: ◇ Headcount by Principal
A19: Principal | B19: Active Employees | C19: Active Teams | D19: Licenses Held
A20: Harsh Vardhan | B20: =COUNTIFS(Master_Employees!D:D,"Harsh Vardhan",Master_Employees!P:P,TRUE()) -> 28 | C20: =COUNTIFS(Groups!C:C,"Harsh Vardhan",Groups!H:H,TRUE()) -> 6 | D20: =SUMPRODUCT((Master_Employees!D2:D1000="Harsh Vardhan")*(Master_Employees!P2:P1000=TRUE())*(Master_Employees!Q2:Q1000)) -> 53
A21: Ambrish Arora | B21: =COUNTIFS(Master_Employees!D:D,"Ambrish Arora",Master_Employees!P:P,TRUE()) -> 25 | C21: =COUNTIFS(Groups!C:C,"Ambrish Arora",Groups!H:H,TRUE()) -> 4 | D21: =SUMPRODUCT((Master_Employees!D2:D1000="Ambrish Arora")*(Master_Employees!P2:P1000=TRUE())*(Master_Employees!Q2:Q1000)) -> 53
A22: Ankur Choksi | B22: =COUNTIFS(Master_Employees!D:D,"Ankur Choksi",Master_Employees!P:P,TRUE()) -> 21 | C22: =COUNTIFS(Groups!C:C,"Ankur Choksi",Groups!H:H,TRUE()) -> 3 | D22: =SUMPRODUCT((Master_Employees!D2:D1000="Ankur Choksi")*(Master_Employees!P2:P1000=TRUE())*(Master_Employees!Q2:Q1000)) -> 39
A23: Asha Sairam | B23: =COUNTIFS(Master_Employees!D:D,"Asha Sairam",Master_Employees!P:P,TRUE()) -> 30 | C23: =COUNTIFS(Groups!C:C,"Asha Sairam",Groups!H:H,TRUE()) -> 4 | D23: =SUMPRODUCT((Master_Employees!D2:D1000="Asha Sairam")*(Master_Employees!P2:P1000=TRUE())*(Master_Employees!Q2:Q1000)) -> 62
A26: ➤ Go to
A28: License_Dashboard | B28: Full software inventory, utilisation and renewal posture
A29: Master_Employees | B29: Source of truth for every person — edit Group Key to re-team
A30: Licenses | B30: One row per user-license assignment; data validation included
A31: License_Inventory | B31: Contracts: vendor, seats, dates, days-to-expiry
A32: Expiring_Soon | B32: ⚠ Watchlist for the next 30 days — change horizon in B2
A33: Group_License_View | B33: Pivot of licenses by team and principal
A34: User_License_Matrix | B34: Who has which tool — cross-tab
A35: Live_Org_Chart | B35: Rendered org tree (rebuilt by Apps Script)
A37: Apps Script — once imported into Google Sheets, paste the provided Code.gs and OrgTree.html into Extensions > Apps Script, then run Studio Lotus Org > Setup Auto Refresh. A daily trigger (sendRenewalDigest) can email itsupport@studiolotus.in when contracts approach expiry.

Sheet Master_Employees
A1: Employee No | B1: Employee Name | C1: Work Email | D1: Principal | E1: Group Key | F1: Group / Team | G1: Team Lead | H1: Org Level | I1: Job Title | J1: Source Reports To | K1: Source Manager Emp No | L1: Manager Override Emp No | M1: Business Unit | N1: Department | O1: Worker Type | P1: Include in Org | Q1: License Count | R1: Notes | S1: DOJ | T1: Prior Exp (yrs) | U1: Image URL | V1: Designation Level | W1: Designation Color
A2: SL0027 | B2: Harsh Vardhan | C2: harsh@studiolotus.in | D2: =IFERROR(VLOOKUP(E2,Groups!$A:$I,3,FALSE()),"Unassigned") -> Harsh Vardhan | E2: HARSH-HOMES | F2: =IFERROR(VLOOKUP(E2,Groups!$A:$I,2,FALSE()),"Unassigned") -> Homes | G2: =IFERROR(VLOOKUP(E2,Groups!$A:$I,4,FALSE()),"Direct Reports") -> Harsh Vardhan | H2: =IF(OR(P2=FALSE(),P2="FALSE"),"Excluded",IF(B2=D2,"Principal",IF(B2=G2,"Team Lead","Member"))) -> Principal | I2: Principal | J2: Ambrish Arora | K2: SL0001 | M2: Studio Lotus | N2: Unit Support | O2: Permanent | P2: =TRUE() -> TRUE | Q2: =COUNTIF(Licenses!$A:$A,C2) -> 0 | S2: 42979 | V2: Principal | W2: #1A2332
A3: SL0244 | B3: Anandita Kaur Narula | C3: anandita.narula@studiolotus.in | D3: =IFERROR(VLOOKUP(E3,Groups!$A:$I,3,FALSE()),"Unassigned") -> Harsh Vardhan | E3: HARSH-HOMES | F3: =IFERROR(VLOOKUP(E3,Groups!$A:$I,2,FALSE()),"Unassigned") -> Homes | G3: =IFERROR(VLOOKUP(E3,Groups!$A:$I,4,FALSE()),"Direct Reports") -> Harsh Vardhan | H3: =IF(OR(P3=FALSE(),P3="FALSE"),"Excluded",IF(B3=D3,"Principal",IF(B3=G3,"Team Lead","Member"))) -> Member | I3: Sr. Architect | J3: Harsh Vardhan | K3: SL0027 | M3: Unit 2 | N3: Residential & Commercial ID & Arch-Unit 2 | O3: Permanent | P3: =TRUE() -> TRUE | Q3: =COUNTIF(Licenses!$A:$A,C3) -> 3 | S3: 45139 | V3: Senior Architect/Designer | W3: #A4853D
A4: SL0272 | B4: Anshika Maheshwari | C4: anshika@studiolotus.in | D4: =IFERROR(VLOOKUP(E4,Groups!$A:$I,3,FALSE()),"Unassigned") -> Harsh Vardhan | E4: HARSH-HOMES | F4: =IFERROR(VLOOKUP(E4,Groups!$A:$I,2,FALSE()),"Unassigned") -> Homes | G4: =IFERROR(VLOOKUP(E4,Groups!$A:$I,4,FALSE()),"Direct Reports") -> Harsh Vardhan | H4: =IF(OR(P4=FALSE(),P4="FALSE"),"Excluded",IF(B4=D4,"Principal",IF(B4=G4,"Team Lead","Member"))) -> Member | I4: Architect | J4: Harsh Vardhan | K4: SL0027 | M4: Unit 2 | N4: Residential & Commercial ID & Arch-Unit 2 | O4: Permanent | P4: =TRUE() -> TRUE | Q4: =COUNTIF(Licenses!$A:$A,C4) -> 3 | S4: 45355 | V4: Architect/Designer | W4: #5D4156
A5: SL0007 | B5: Kavita Chatola | C5: kavita@studiolotus.in | D5: =IFERROR(VLOOKUP(E5,Groups!$A:$I,3,FALSE()),"Unassigned") -> Harsh Vardhan | E5: HARSH-ADMIN | F5: =IFERROR(VLOOKUP(E5,Groups!$A:$I,2,FALSE()),"Unassigned") -> Admin & Infra | G5: =IFERROR(VLOOKUP(E5,Groups!$A:$I,4,FALSE()),"Direct Reports") -> Kavita Chatola | H5: =IF(OR(P5=FALSE(),P5="FALSE"),"Excluded",IF(B5=D5,"Principal",IF(B5=G5,"Team Lead","Member"))) -> Team Lead | I5: Manager Administration | J5: Harsh Vardhan | K5: SL0027 | M5: Studio Lotus | N5: Unit Support | O5: Permanent | P5: =TRUE() -> TRUE | Q5: =COUNTIF(Licenses!$A:$A,C5) -> 2 | S5: 40692 | V5: Support | W5: #707A87
A6: SL0203 | B6: Maitrayee Takale | C6: maitrayee@studiolotus.in | D6: =IFERROR(VLOOKUP(E6,Groups!$A:$I,3,FALSE()),"Unassigned") -> Harsh Vardhan | E6: HARSH-HOMES | F6: =IFERROR(VLOOKUP(E6,Groups!$A:$I,2,FALSE()),"Unassigned") -> Homes | G6: =IFERROR(VLOOKUP(E6,Groups!$A:$I,4,FALSE()),"Direct Reports") -> Harsh Vardhan | H6: =IF(OR(P6=FALSE(),P6="FALSE"),"Excluded",IF(B6=D6,"Principal",IF(B6=G6,"Team Lead","Member"))) -> Member | I6: Sr. Architect | J6: Harsh Vardhan | K6: SL0027 | M6: Unit 2 | N6: Residential & Commercial ID & Arch-Unit 2 | O6: Permanent | P6: =TRUE() -> TRUE | Q6: =COUNTIF(Licenses!$A:$A,C6) -> 2 | S6: 44879 | V6: Senior Architect/Designer | W6: #A4853D
A7: SL0302 | B7: Sarthak Sharma | C7: sarthak.sharma@studiolotus.in | D7: =IFERROR(VLOOKUP(E7,Groups!$A:$I,3,FALSE()),"Unassigned") -> Harsh Vardhan | E7: HARSH-HOMES | F7: =IFERROR(VLOOKUP(E7,Groups!$A:$I,2,FALSE()),"Unassigned") -> Homes | G7: =IFERROR(VLOOKUP(E7,Groups!$A:$I,4,FALSE()),"Direct Reports") -> Harsh Vardhan | H7: =IF(OR(P7=FALSE(),P7="FALSE"),"Excluded",IF(B7=D7,"Principal",IF(B7=G7,"Team Lead","Member"))) -> Member | I7: Architect | J7: Harsh Vardhan | K7: SL0027 | M7: Unit 2 | N7: Residential & Commercial ID & Arch-Unit 2 | O7: Permanent | P7: =TRUE() -> TRUE | Q7: =COUNTIF(Licenses!$A:$A,C7) -> 2 | S7: 45539 | V7: Architect/Designer | W7: #5D4156
A8: SL0063 | B8: Tanvi Jain | C8: tanvi@studiolotus.in | D8: =IFERROR(VLOOKUP(E8,Groups!$A:$I,3,FALSE()),"Unassigned") -> Harsh Vardhan | E8: HARSH-BD | F8: =IFERROR(VLOOKUP(E8,Groups!$A:$I,2,FALSE()),"Unassigned") -> BD & Comms | G8: =IFERROR(VLOOKUP(E8,Groups!$A:$I,4,FALSE()),"Direct Reports") -> Amita Goel | H8: =IF(OR(P8=FALSE(),P8="FALSE"),"Excluded",IF(B8=D8,"Principal",IF(B8=G8,"Team Lead","Member"))) -> Member | I8: Engagement Manager- Business Development | J8: Harsh Vardhan | K8: SL0027 | M8: Studio Lotus | N8: Unit Support | O8: Permanent | P8: =TRUE() -> TRUE | Q8: =COUNTIF(Licenses!$A:$A,C8) -> 2 | S8: 43556 | V8: Support | W8: #707A87
A9: SL0338 | B9: Aditi Agashe | C9: aditi.agashe@studiolotus.in | D9: =IFERROR(VLOOKUP(E9,Groups!$A:$I,3,FALSE()),"Unassigned") -> Harsh Vardhan | E9: HARSH-HOMES | F9: =IFERROR(VLOOKUP(E9,Groups!$A:$I,2,FALSE()),"Unassigned") -> Homes | G9: =IFERROR(VLOOKUP(E9,Groups!$A:$I,4,FALSE()),"Direct Reports") -> Harsh Vardhan | H9: =IF(OR(P9=FALSE(),P9="FALSE"),"Excluded",IF(B9=D9,"Principal",IF(B9=G9,"Team Lead","Member"))) -> Member | I9: Project Architect | J9: Harsh Vardhan | K9: SL0027 | M9: Unit 2 | N9: Residential & Commercial ID & Arch-Unit 2 | O9: Permanent | P9: =TRUE() -> TRUE | Q9: =COUNTIF(Licenses!$A:$A,C9) -> 2 | S9: 45909 | V9: Project Architect/Designer | W9: #8A4A35
A10: 453 | B10: Ambar Agarwal | C10: ambar.agarwal@studiolotus.in | D10: =IFERROR(VLOOKUP(E10,Groups!$A:$I,3,FALSE()),"Unassigned") -> Harsh Vardhan | E10: HARSH-HOMES | F10: =IFERROR(VLOOKUP(E10,Groups!$A:$I,2,FALSE()),"Unassigned") -> Homes | G10: =IFERROR(VLOOKUP(E10,Groups!$A:$I,4,FALSE()),"Direct Reports") -> Harsh Vardhan | H10: =IF(OR(P10=FALSE(),P10="FALSE"),"Excluded",IF(B10=D10,"Principal",IF(B10=G10,"Team Lead","Member"))) -> Member | I10: Intern | J10: Aditi Agashe | K10: SL0338 | M10: Unit 2 | N10: Residential & Commercial ID & Arch-Unit 2 | O10: Intern | P10: =TRUE() -> TRUE | Q10: =COUNTIF(Licenses!$A:$A,C10) -> 1 | S10: 46055 | V10: Intern | W10: #97A0AB
A11: SL0224 | B11: Amita Goel | C11: amita@studiolotus.in | D11: =IFERROR(VLOOKUP(E11,Groups!$A:$I,3,FALSE()),"Unassigned") -> Harsh Vardhan | E11: HARSH-BD | F11: =IFERROR(VLOOKUP(E11,Groups!$A:$I,2,FALSE()),"Unassigned") -> BD & Comms | G11: =IFERROR(VLOOKUP(E11,Groups!$A:$I,4,FALSE()),"Direct Reports") -> Amita Goel | H11: =IF(OR(P11=FALSE(),P11="FALSE"),"Excluded",IF(B11=D11,"Principal",IF(B11=G11,"Team Lead","Member"))) -> Team Lead | I11: Associate Principal | J11: Harsh Vardhan | K11: SL0027 | M11: Studio Lotus | N11: Unit Support | O11: Permanent | P11: =TRUE() -> TRUE | Q11: =COUNTIF(Licenses!$A:$A,C11) -> 1 | S11: 45082 | V11: Associate Principal | W11: #2E4057
A12: SL0249 | B12: Atharv Subharwal | C12: atharv@studiolotus.in | D12: =IFERROR(VLOOKUP(E12,Groups!$A:$I,3,FALSE()),"Unassigned") -> Harsh Vardhan | E12: HARSH-BD | F12: =IFERROR(VLOOKUP(E12,Groups!$A:$I,2,FALSE()),"Unassigned") -> BD & Comms | G12: =IFERROR(VLOOKUP(E12,Groups!$A:$I,4,FALSE()),"Direct Reports") -> Amita Goel | H12: =IF(OR(P12=FALSE(),P12="FALSE"),"Excluded",IF(B12=D12,"Principal",IF(B12=G12,"Team Lead","Member"))) -> Member | I12: Sr. 3D Artist | J12: Amita Goel | K12: SL0224 | M12: Studio Lotus | N12: Unit Support | O12: Permanent | P12: =TRUE() -> TRUE | Q12: =COUNTIF(Licenses!$A:$A,C12) -> 6 | S12: 45166 | V12: Support | W12: #707A87
A13: SL0236 | B13: Bharati Asmita | C13: asmita.bharati@studiolotus.in | D13: =IFERROR(VLOOKUP(E13,Groups!$A:$I,3,FALSE()),"Unassigned") -> Harsh Vardhan | E13: HARSH-BD | F13: =IFERROR(VLOOKUP(E13,Groups!$A:$I,2,FALSE()),"Unassigned") -> BD & Comms | G13: =IFERROR(VLOOKUP(E13,Groups!$A:$I,4,FALSE()),"Direct Reports") -> Amita Goel | H13: =IF(OR(P13=FALSE(),P13="FALSE"),"Excluded",IF(B13=D13,"Principal",IF(B13=G13,"Team Lead","Member"))) -> Member | I13: Communications Manager | J13: Amita Goel | K13: SL0224 | M13: Studio Lotus | N13: Unit Support | O13: Permanent | P13: =TRUE() -> TRUE | Q13: =COUNTIF(Licenses!$A:$A,C13) -> 6 | S13: 45119 | V13: Support | W13: #707A87
... A20: 9 | B20: Vikram Singh | C20: vikram056085@gmail.com | D20: =IFERROR(VLOOKUP(E20,Groups!$A:$I,3,FALSE()),"Unassigned") -> Harsh Vardhan | E20: HARSH-ADMIN | F20: =IFERROR(VLOOKUP(E20,Groups!$A:$I,2,FALSE()),"Unassigned") -> Admin & Infra | G20: =IFERROR(VLOOKUP(E20,Groups!$A:$I,4,FALSE()),"Direct Reports") -> Kavita Chatola | H20: =IF(OR(P20=FALSE(),P20="FALSE"),"Excluded",IF(B20=D20,"Principal",IF(B20=G20,"Team Lead","Member"))) -> Member | I20: Office Support | J20: Atul Kumar Singh | K20: SL0266 | M20: Studio Lotus | N20: Unit Support | O20: Permanent | P20: =TRUE() -> TRUE | Q20: =COUNTIF(Licenses!$A:$A,C20) -> 0 | S20: 40957 | V20: Support | W20: #707A87
A21: SL0343 | B21: Devdutt Kumar | C21: devdutt.kumar@studiolotus.in | D21: =IFERROR(VLOOKUP(E21,Groups!$A:$I,3,FALSE()),"Unassigned") -> Harsh Vardhan | E21: HARSH-IT | F21: =IFERROR(VLOOKUP(E21,Groups!$A:$I,2,FALSE()),"Unassigned") -> IT & Tech | G21: =IFERROR(VLOOKUP(E21,Groups!$A:$I,4,FALSE()),"Direct Reports") -> Devdutt Kumar | H21: =IF(OR(P21=FALSE(),P21="FALSE"),"Excluded",IF(B21=D21,"Principal",IF(B21=G21,"Team Lead","Member"))) -> Team Lead | I21: Senior Software Engineer, Data Platform | J21: Harsh Vardhan | K21: SL0027 | M21: Studio Lotus | N21: Unit Support | O21: Permanent | P21: =TRUE() -> TRUE | Q21: =COUNTIF(Licenses!$A:$A,C21) -> 2 | S21: 45964 | T21: 3.5 | V21: Support | W21: #707A87
A22: SL0090 | B22: Nitayee Das | C22: itsupport@studiolotus.in | D22: =IFERROR(VLOOKUP(E22,Groups!$A:$I,3,FALSE()),"Unassigned") -> Harsh Vardhan | E22: HARSH-IT | F22: =IFERROR(VLOOKUP(E22,Groups!$A:$I,2,FALSE()),"Unassigned") -> IT & Tech | G22: =IFERROR(VLOOKUP(E22,Groups!$A:$I,4,FALSE()),"Direct Reports") -> Devdutt Kumar | H22: =IF(OR(P22=FALSE(),P22="FALSE"),"Excluded",IF(B22=D22,"Principal",IF(B22=G22,"Team Lead","Member"))) -> Member | I22: Manager (Information Technology) | J22: Devdutt Kumar | K22: SL0343 | M22: Studio Lotus | N22: Unit Support | O22: Permanent | P22: =TRUE() -> TRUE | Q22: =COUNTIF(Licenses!$A:$A,C22) -> 3 | S22: 43822 | V22: Support | W22: #707A87
A23: SL0321 | B23: Sachin Tyagi | C23: sachin.tyagi@studiolotus.in | D23: =IFERROR(VLOOKUP(E23,Groups!$A:$I,3,FALSE()),"Unassigned") -> Harsh Vardhan | E23: HARSH-IT | F23: =IFERROR(VLOOKUP(E23,Groups!$A:$I,2,FALSE()),"Unassigned") -> IT & Tech | G23: =IFERROR(VLOOKUP(E23,Groups!$A:$I,4,FALSE()),"Direct Reports") -> Devdutt Kumar | H23: =IF(OR(P23=FALSE(),P23="FALSE"),"Excluded",IF(B23=D23,"Principal",IF(B23=G23,"Team Lead","Member"))) -> Member | I23: Senior Manager - IT | J23: Devdutt Kumar | K23: SL0343 | M23: Studio Lotus | N23: Unit Support | O23: Permanent | P23: =TRUE() -> TRUE | Q23: =COUNTIF(Licenses!$A:$A,C23) -> 3 | S23: 45726 | V23: Support | W23: #707A87
A24: SL0356 | B24: Isha Singh | C24: isha.singh@studiolotus.in | D24: =IFERROR(VLOOKUP(E24,Groups!$A:$I,3,FALSE()),"Unassigned") -> Harsh Vardhan | E24: HARSH-PEOPLE | F24: =IFERROR(VLOOKUP(E24,Groups!$A:$I,2,FALSE()),"Unassigned") -> People & Culture | G24: =IFERROR(VLOOKUP(E24,Groups!$A:$I,4,FALSE()),"Direct Reports") -> Isha Singh | H24: =IF(OR(P24=FALSE(),P24="FALSE"),"Excluded",IF(B24=D24,"Principal",IF(B24=G24,"Team Lead","Member"))) -> Team Lead | I24: Senior Manager- Human Resources | J24: Harsh Vardhan | K24: SL0027 | M24: Studio Lotus | N24: Unit Support | O24: Permanent | P24: =TRUE() -> TRUE | Q24: =COUNTIF(Licenses!$A:$A,C24) -> 1 | S24: 46069 | V24: Support | W24: #707A87
A25: SL0157 | B25: Nishant Singh | C25: nishant.singh@studiolotus.in | D25: =IFERROR(VLOOKUP(E25,Groups!$A:$I,3,FALSE()),"Unassigned") -> Harsh Vardhan | E25: HARSH-PEOPLE | F25: =IFERROR(VLOOKUP(E25,Groups!$A:$I,2,FALSE()),"Unassigned") -> People & Culture | G25: =IFERROR(VLOOKUP(E25,Groups!$A:$I,4,FALSE()),"Direct Reports") -> Isha Singh | H25: =IF(OR(P25=FALSE(),P25="FALSE"),"Excluded",IF(B25=D25,"Principal",IF(B25=G25,"Team Lead","Member"))) -> Member | I25: Administrator Human Resources | J25: Isha Singh | K25: SL0356 | M25: Studio Lotus | N25: Unit Support | O25: Permanent | P25: =TRUE() -> TRUE | Q25: =COUNTIF(Licenses!$A:$A,C25) -> 2 | S25: 44298 | V25: Support | W25: #707A87
A26: SL0001 | B26: Ambrish Arora | C26: ambrish@studiolotus.in | D26: =IFERROR(VLOOKUP(E26,Groups!$A:$I,3,FALSE()),"Unassigned") -> Ambrish Arora | E26: AMB-DIRECT | F26: =IFERROR(VLOOKUP(E26,Groups!$A:$I,2,FALSE()),"Unassigned") -> Direct Reports | G26: =IFERROR(VLOOKUP(E26,Groups!$A:$I,4,FALSE()),"Direct Reports") -> Ambrish Arora | H26: =IF(OR(P26=FALSE(),P26="FALSE"),"Excluded",IF(B26=D26,"Principal",IF(B26=G26,"Team Lead","Member"))) -> Principal | I26: Principal | J26: Ambrish Arora | K26: SL0001 | M26: Studio Lotus | N26: Architecture Unit 1 | O26: Permanent | P26: =TRUE() -> TRUE | Q26: =COUNTIF(Licenses!$A:$A,C26) -> 0 | S26: 37299 | V26: Principal | W26: #1A2332
A27: SL0098 | B27: Prajwal Yashwant Amin | C27: prajwal@studiolotus.in | D27: =IFERROR(VLOOKUP(E27,Groups!$A:$I,3,FALSE()),"Unassigned") -> Ambrish Arora | E27: AMB-PRAJWAL | F27: =IFERROR(VLOOKUP(E27,Groups!$A:$I,2,FALSE()),"Unassigned") -> Prajwal Yashwant Amin Team | G27: =IFERROR(VLOOKUP(E27,Groups!$A:$I,4,FALSE()),"Direct Reports") -> Prajwal Yashwant Amin | H27: =IF(OR(P27=FALSE(),P27="FALSE"),"Excluded",IF(B27=D27,"Principal",IF(B27=G27,"Team Lead","Member"))) -> Team Lead | I27: Project Architect | J27: Ambrish Arora | K27: SL0001 | M27: Unit 1 | N27: Architecture Unit 1 | O27: Permanent | P27: =TRUE() -> TRUE | Q27: =COUNTIF(Licenses!$A:$A,C27) -> 4 | S27: 44153 | V27: Project Architect/Designer | W27: #8A4A35
A28: SL0250 | B28: Aditi Panwar | C28: aditi.panwar@studiolotus.in | D28: =IFERROR(VLOOKUP(E28,Groups!$A:$I,3,FALSE()),"Unassigned") -> Ambrish Arora | E28: AMB-PRAJWAL | F28: =IFERROR(VLOOKUP(E28,Groups!$A:$I,2,FALSE()),"Unassigned") -> Prajwal Yashwant Amin Team | G28: =IFERROR(VLOOKUP(E28,Groups!$A:$I,4,FALSE()),"Direct Reports") -> Prajwal Yashwant Amin | H28: =IF(OR(P28=FALSE(),P28="FALSE"),"Excluded",IF(B28=D28,"Principal",IF(B28=G28,"Team Lead","Member"))) -> Member | I28: Architect | J28: Prajwal Yashwant Amin | K28: SL0098 | M28: Unit 1 | N28: Architecture Unit 1 | O28: Permanent | P28: =TRUE() -> TRUE | Q28: =COUNTIF(Licenses!$A:$A,C28) -> 3 | S28: 45175 | V28: Architect/Designer | W28: #5D4156
A29: SL0352 | B29: Ayushi Patwari | C29: ayushi.patwari@studiolotus.in | D29: =IFERROR(VLOOKUP(E29,Groups!$A:$I,3,FALSE()),"Unassigned") -> Ambrish Arora | E29: AMB-PRAJWAL | F29: =IFERROR(VLOOKUP(E29,Groups!$A:$I,2,FALSE()),"Unassigned") -> Prajwal Yashwant Amin Team | G29: =IFERROR(VLOOKUP(E29,Groups!$A:$I,4,FALSE()),"Direct Reports") -> Prajwal Yashwant Amin | H29: =IF(OR(P29=FALSE(),P29="FALSE"),"Excluded",IF(B29=D29,"Principal",IF(B29=G29,"Team Lead","Member"))) -> Member | I29: Architect | J29: Prajwal Yashwant Amin | K29: SL0098 | M29: Unit 1 | N29: Architecture Unit 1 | O29: Permanent | P29: =TRUE() -> TRUE | Q29: =COUNTIF(Licenses!$A:$A,C29) -> 3 | S29: 46041 | V29: Architect/Designer | W29: #5D4156
A30: SL0307 | B30: Puru Bhatia | C30: puru.bhatia@studiolotus.in | D30: =IFERROR(VLOOKUP(E30,Groups!$A:$I,3,FALSE()),"Unassigned") -> Ambrish Arora | E30: AMB-PRAJWAL | F30: =IFERROR(VLOOKUP(E30,Groups!$A:$I,2,FALSE()),"Unassigned") -> Prajwal Yashwant Amin Team | G30: =IFERROR(VLOOKUP(E30,Groups!$A:$I,4,FALSE()),"Direct Reports") -> Prajwal Yashwant Amin | H30: =IF(OR(P30=FALSE(),P30="FALSE"),"Excluded",IF(B30=D30,"Principal",IF(B30=G30,"Team Lead","Member"))) -> Member | I30: Architect | J30: Prajwal Yashwant Amin | K30: SL0098 | M30: Unit 1 | N30: Architecture Unit 1 | O30: Permanent | P30: =TRUE() -> TRUE | Q30: =COUNTIF(Licenses!$A:$A,C30) -> 2 | S30: 45558 | V30: Architect/Designer | W30: #5D4156
A31: SL0330 | B31: Suhani Khandelwal | C31: suhani.khandelwal@studiolotus.in | D31: =IFERROR(VLOOKUP(E31,Groups!$A:$I,3,FALSE()),"Unassigned") -> Ambrish Arora | E31: AMB-PRAJWAL | F31: =IFERROR(VLOOKUP(E31,Groups!$A:$I,2,FALSE()),"Unassigned") -> Prajwal Yashwant Amin Team | G31: =IFERROR(VLOOKUP(E31,Groups!$A:$I,4,FALSE()),"Direct Reports") -> Prajwal Yashwant Amin | H31: =IF(OR(P31=FALSE(),P31="FALSE"),"Excluded",IF(B31=D31,"Principal",IF(B31=G31,"Team Lead","Member"))) -> Member | I31: Architect | J31: Prajwal Yashwant Amin | K31: SL0098 | M31: Unit 1 | N31: Architecture Unit 1 | O31: Permanent | P31: =TRUE() -> TRUE | Q31: =COUNTIF(Licenses!$A:$A,C31) -> 3 | S31: 45859 | V31: Architect/Designer | W31: #5D4156
A32: SL0006 | B32: Rajendra Kumar Mohanty | C32: rajendra@studiolotus.in | D32: =IFERROR(VLOOKUP(E32,Groups!$A:$I,3,FALSE()),"Unassigned") -> Harsh Vardhan | E32: HARSH-FINANCE | F32: =IFERROR(VLOOKUP(E32,Groups!$A:$I,2,FALSE()),"Unassigned") -> Finance & Accounts | G32: =IFERROR(VLOOKUP(E32,Groups!$A:$I,4,FALSE()),"Direct Reports") -> Rajendra Kumar Mohanty | H32: =IF(OR(P32=FALSE(),P32="FALSE"),"Excluded",IF(B32=D32,"Principal",IF(B32=G32,"Team Lead","Member"))) -> Team Lead | I32: Head Finance and Accounts | J32: Ambrish Arora | K32: SL0001 | M32: Studio Lotus | N32: Unit Support | O32: Permanent | P32: =TRUE() -> TRUE | Q32: =COUNTIF(Licenses!$A:$A,C32) -> 4 | S32: 40247 | V32: Support | W32: #707A87
A33: SL0305 | B33: Aman Jha | C33: accountsexecutive@studiolotus.in | D33: Harsh Vardhan | E33: HARSH-FINANCE | F33: Finance & Accounts | G33: Rajendra Kumar Mohanty | H33: =IF(OR(P33=FALSE(),P33="FALSE"),"Excluded",IF(B33=D33,"Principal",IF(B33=G33,"Team Lead","Member"))) -> Member | I33: Accounts Executive | J33: Rajendra Kumar Mohanty | K33: SL0006 | M33: Studio Lotus | N33: Unit Support | O33: Permanent | P33: =TRUE() -> TRUE | Q33: =COUNTIF(Licenses!$A:$A,C33) -> 0 | S33: 45566 | V33: Support | W33: #707A87
A34: 77 | B34: HR Studio Lotus | C34: hr@studiolotus.in | D34: =IFERROR(VLOOKUP(E34,Groups!$A:$I,3,FALSE()),"Unassigned") -> Harsh Vardhan | E34: HARSH-PEOPLE | F34: =IFERROR(VLOOKUP(E34,Groups!$A:$I,2,FALSE()),"Unassigned") -> People & Culture | G34: =IFERROR(VLOOKUP(E34,Groups!$A:$I,4,FALSE()),"Direct Reports") -> Isha Singh | H34: =IF(OR(P34=FALSE(),P34="FALSE"),"Excluded",IF(B34=D34,"Principal",IF(B34=G34,"Team Lead","Member"))) -> Member | I34: Human Resources Head | J34: Nirmal Singh Bhakuni | K34: SL0008 | M34: Studio Lotus | N34: Unit Support | O34: Permanent | P34: =TRUE() -> TRUE | Q34: =COUNTIF(Licenses!$A:$A,C34) -> 0 | S34: 44866 | V34: Support | W34: #707A87
A35: SL0008 | B35: Nirmal Singh Bhakuni | C35: nirmal@studiolotus.in | D35: =IFERROR(VLOOKUP(E35,Groups!$A:$I,3,FALSE()),"Unassigned") -> Harsh Vardhan | E35: HARSH-FINANCE | F35: =IFERROR(VLOOKUP(E35,Groups!$A:$I,2,FALSE()),"Unassigned") -> Finance & Accounts | G35: =IFERROR(VLOOKUP(E35,Groups!$A:$I,4,FALSE()),"Direct Reports") -> Rajendra Kumar Mohanty | H35: =IF(OR(P35=FALSE(),P35="FALSE"),"Excluded",IF(B35=D35,"Principal",IF(B35=G35,"Team Lead","Member"))) -> Member | I35: Assistant Manager -Accounts | J35: Rajendra Kumar Mohanty | K35: SL0006 | M35: Studio Lotus | N35: Unit Support | O35: Permanent | P35: =TRUE() -> TRUE | Q35: =COUNTIF(Licenses!$A:$A,C35) -> 4 | S35: 42065 | V35: Support | W35: #707A87
A36: SL0314 | B36: Varun Srivastava | C36: varun.srivastava@studiolotus.in | D36: =IFERROR(VLOOKUP(E36,Groups!$A:$I,3,FALSE()),"Unassigned") -> Ambrish Arora | E36: AMB-VARUN | F36: =IFERROR(VLOOKUP(E36,Groups!$A:$I,2,FALSE()),"Unassigned") -> Varun Srivastava Team | G36: =IFERROR(VLOOKUP(E36,Groups!$A:$I,4,FALSE()),"Direct Reports") -> Varun Srivastava | H36: =IF(OR(P36=FALSE(),P36="FALSE"),"Excluded",IF(B36=D36,"Principal",IF(B36=G36,"Team Lead","Member"))) -> Team Lead | I36: Group Leader | J36: Ambrish Arora | K36: SL0001 | M36: Unit 1 | N36: Architecture Unit 1 | O36: Permanent | P36: =TRUE() -> TRUE | Q36: =COUNTIF(Licenses!$A:$A,C36) -> 3 | S36: 45659 | V36: Group Leader | W36: #475E4A
A37: SL0333 | B37: Adhiraj Sirkeck | C37: adhiraj.sirkeck@studiolotus.in | D37: =IFERROR(VLOOKUP(E37,Groups!$A:$I,3,FALSE()),"Unassigned") -> Ambrish Arora | E37: AMB-VARUN | F37: =IFERROR(VLOOKUP(E37,Groups!$A:$I,2,FALSE()),"Unassigned") -> Varun Srivastava Team | G37: =IFERROR(VLOOKUP(E37,Groups!$A:$I,4,FALSE()),"Direct Reports") -> Varun Srivastava | H37: =IF(OR(P37=FALSE(),P37="FALSE"),"Excluded",IF(B37=D37,"Principal",IF(B37=G37,"Team Lead","Member"))) -> Member | I37: Sr. Architect | J37: Varun Srivastava | K37: SL0314 | M37: Unit 1 | N37: Architecture Unit 1 | O37: Permanent | P37: =TRUE() -> TRUE | Q37: =COUNTIF(Licenses!$A:$A,C37) -> 2 | S37: 45873 | V37: Senior Architect/Designer | W37: #A4853D
A38: SL0299 | B38: Harsha Singh | C38: harsha.singh@studiolotus.in | D38: =IFERROR(VLOOKUP(E38,Groups!$A:$I,3,FALSE()),"Unassigned") -> Ambrish Arora | E38: AMB-VARUN | F38: =IFERROR(VLOOKUP(E38,Groups!$A:$I,2,FALSE()),"Unassigned") -> Varun Srivastava Team | G38: =IFERROR(VLOOKUP(E38,Groups!$A:$I,4,FALSE()),"Direct Reports") -> Varun Srivastava | H38: =IF(OR(P38=FALSE(),P38="FALSE"),"Excluded",IF(B38=D38,"Principal",IF(B38=G38,"Team Lead","Member"))) -> Member | I38: Architect | J38: Varun Srivastava | K38: SL0314 | M38: Unit 1 | N38: Architecture Unit 1 | O38: Permanent | P38: =TRUE() -> TRUE | Q38: =COUNTIF(Licenses!$A:$A,C38) -> 2 | S38: 45532 | V38: Architect/Designer | W38: #5D4156
A39: SL0357 | B39: Khushboo Pandey | C39: khushboo.pandey@studiolotus.in | D39: =IFERROR(VLOOKUP(E39,Groups!$A:$I,3,FALSE()),"Unassigned") -> Ambrish Arora | E39: AMB-VARUN | F39: =IFERROR(VLOOKUP(E39,Groups!$A:$I,2,FALSE()),"Unassigned") -> Varun Srivastava Team | G39: =IFERROR(VLOOKUP(E39,Groups!$A:$I,4,FALSE()),"Direct Reports") -> Varun Srivastava | H39: =IF(OR(P39=FALSE(),P39="FALSE"),"Excluded",IF(B39=D39,"Principal",IF(B39=G39,"Team Lead","Member"))) -> Member | I39: Project Architect | J39: Varun Srivastava | K39: SL0314 | M39: Unit 1 | N39: Architecture Unit 1 | O39: Permanent | P39: =TRUE() -> TRUE | Q39: =COUNTIF(Licenses!$A:$A,C39) -> 1 | S39: 46086 | V39: Project Architect/Designer | W39: #8A4A35
A40: SL0318 | B40: Nikita Bhatia | C40: nikita.bhatia@studiolotus.in | D40: =IFERROR(VLOOKUP(E40,Groups!$A:$I,3,FALSE()),"Unassigned") -> Ambrish Arora | E40: AMB-VARUN | F40: =IFERROR(VLOOKUP(E40,Groups!$A:$I,2,FALSE()),"Unassigned") -> Varun Srivastava Team | G40: =IFERROR(VLOOKUP(E40,Groups!$A:$I,4,FALSE()),"Direct Reports") -> Varun Srivastava | H40: =IF(OR(P40=FALSE(),P40="FALSE"),"Excluded",IF(B40=D40,"Principal",IF(B40=G40,"Team Lead","Member"))) -> Member | I40: Project Architect | J40: Varun Srivastava | K40: SL0314 | M40: Unit 1 | N40: Architecture Unit 1 | O40: Permanent | P40: =TRUE() -> TRUE | Q40: =COUNTIF(Licenses!$A:$A,C40) -> 2 | S40: 45692 | V40: Project Architect/Designer | W40: #8A4A35
A41: SL0263 | B41: Rida Drabu | C41: rida@studiolotus.in | D41: =IFERROR(VLOOKUP(E41,Groups!$A:$I,3,FALSE()),"Unassigned") -> Ambrish Arora | E41: AMB-VARUN | F41: =IFERROR(VLOOKUP(E41,Groups!$A:$I,2,FALSE()),"Unassigned") -> Varun Srivastava Team | G41: =IFERROR(VLOOKUP(E41,Groups!$A:$I,4,FALSE()),"Direct Reports") -> Varun Srivastava | H41: =IF(OR(P41=FALSE(),P41="FALSE"),"Excluded",IF(B41=D41,"Principal",IF(B41=G41,"Team Lead","Member"))) -> Member | I41: Architect | J41: Varun Srivastava | K41: SL0314 | M41: Unit 1 | N41: Architecture Unit 1 | O41: Permanent | P41: =TRUE() -> TRUE | Q41: =COUNTIF(Licenses!$A:$A,C41) -> 2 | S41: 45286 | V41: Architect/Designer | W41: #5D4156
A42: SL0289 | B42: Rushil Jain | C42: rushil.jain@studiolotus.in | D42: =IFERROR(VLOOKUP(E42,Groups!$A:$I,3,FALSE()),"Unassigned") -> Ambrish Arora | E42: AMB-VARUN | F42: =IFERROR(VLOOKUP(E42,Groups!$A:$I,2,FALSE()),"Unassigned") -> Varun Srivastava Team | G42: =IFERROR(VLOOKUP(E42,Groups!$A:$I,4,FALSE()),"Direct Reports") -> Varun Srivastava | H42: =IF(OR(P42=FALSE(),P42="FALSE"),"Excluded",IF(B42=D42,"Principal",IF(B42=G42,"Team Lead","Member"))) -> Member | I42: Architect | J42: Varun Srivastava | K42: SL0314 | M42: Unit 1 | N42: Architecture Unit 1 | O42: Permanent | P42: =TRUE() -> TRUE | Q42: =COUNTIF(Licenses!$A:$A,C42) -> 3 | S42: 45474 | V42: Architect/Designer | W42: #5D4156
A43: SL0220 | B43: Satwik Singh Rathour | C43: satwik@studiolotus.in | D43: =IFERROR(VLOOKUP(E43,Groups!$A:$I,3,FALSE()),"Unassigned") -> Ambrish Arora | E43: AMB-VARUN | F43: =IFERROR(VLOOKUP(E43,Groups!$A:$I,2,FALSE()),"Unassigned") -> Varun Srivastava Team | G43: =IFERROR(VLOOKUP(E43,Groups!$A:$I,4,FALSE()),"Direct Reports") -> Varun Srivastava | H43: =IF(OR(P43=FALSE(),P43="FALSE"),"Excluded",IF(B43=D43,"Principal",IF(B43=G43,"Team Lead","Member"))) -> Member | I43: Sr. Architect | J43: Varun Srivastava | K43: SL0314 | M43: Unit 1 | N43: Architecture Unit 1 | O43: Permanent | P43: =TRUE() -> TRUE | Q43: =COUNTIF(Licenses!$A:$A,C43) -> 3 | S43: 45082 | V43: Senior Architect/Designer | W43: #A4853D
A44: SL0204 | B44: Vivin Neelankavil | C44: vivin@studiolotus.in | D44: =IFERROR(VLOOKUP(E44,Groups!$A:$I,3,FALSE()),"Unassigned") -> Ambrish Arora | E44: AMB-VARUN | F44: =IFERROR(VLOOKUP(E44,Groups!$A:$I,2,FALSE()),"Unassigned") -> Varun Srivastava Team | G44: =IFERROR(VLOOKUP(E44,Groups!$A:$I,4,FALSE()),"Direct Reports") -> Varun Srivastava | H44: =IF(OR(P44=FALSE(),P44="FALSE"),"Excluded",IF(B44=D44,"Principal",IF(B44=G44,"Team Lead","Member"))) -> Member | I44: Sr. Architect | J44: Varun Srivastava | K44: SL0314 | M44: Unit 1 | N44: Architecture Unit 1 | O44: Permanent | P44: =TRUE() -> TRUE | Q44: =COUNTIF(Licenses!$A:$A,C44) -> 3 | S44: 44886 | V44: Senior Architect/Designer | W44: #A4853D
A45: SL0150 | B45: Yatin Tokas | C45: yatin.tokas@studiolotus.in | D45: =IFERROR(VLOOKUP(E45,Groups!$A:$I,3,FALSE()),"Unassigned") -> Ambrish Arora | E45: AMB-YATIN | F45: =IFERROR(VLOOKUP(E45,Groups!$A:$I,2,FALSE()),"Unassigned") -> Yatin Tokas Team | G45: =IFERROR(VLOOKUP(E45,Groups!$A:$I,4,FALSE()),"Direct Reports") -> Yatin Tokas | H45: =IF(OR(P45=FALSE(),P45="FALSE"),"Excluded",IF(B45=D45,"Principal",IF(B45=G45,"Team Lead","Member"))) -> Team Lead | I45: Project Lead | J45: Ambrish Arora | K45: SL0001 | M45: Unit 1 | N45: Architecture Unit 1 | O45: Permanent | P45: =TRUE() -> TRUE | Q45: =COUNTIF(Licenses!$A:$A,C45) -> 3 | S45: 44440 | V45: Group Leader | W45: #475E4A
... A48: SL0303 | B48: Jagdish Samal | C48: jagdish.samal@studiolotus.in | D48: =IFERROR(VLOOKUP(E48,Groups!$A:$I,3,FALSE()),"Unassigned") -> Ambrish Arora | E48: AMB-YATIN | F48: =IFERROR(VLOOKUP(E48,Groups!$A:$I,2,FALSE()),"Unassigned") -> Yatin Tokas Team | G48: =IFERROR(VLOOKUP(E48,Groups!$A:$I,4,FALSE()),"Direct Reports") -> Yatin Tokas | H48: =IF(OR(P48=FALSE(),P48="FALSE"),"Excluded",IF(B48=D48,"Principal",IF(B48=G48,"Team Lead","Member"))) -> Member | I48: Architect | J48: Yatin Tokas | K48: SL0150 | M48: Unit 1 | N48: Architecture Unit 1 | O48: Permanent | P48: =TRUE() -> TRUE | Q48: =COUNTIF(Licenses!$A:$A,C48) -> 1 | S48: 45544 | V48: Architect/Designer | W48: #5D4156
...

Sheet Shared_Accounts
A1: Email | B1: Display Name | C1: Type | D1: Notes
A2: sm@studiolotus.in | B2: Studio Lotus (shared) | C2: Shared Account | D2: Common Adobe account — no individual owner
A3: principal@tacdesign.onmicrosoft.com | B3: Principal Room | C3: Meeting Room | D3: Office License
A4: kishan@studiolotus.in | B4: Kishan Sirohi | C4: Service Account | D4: Consultant

Sheet Licenses
A1: Work Email | B1: License / Tool | C1: Plan / People | D1: Status | E1: Assigned On | F1: Renewal / End Date | G1: Cost Centre / Team | H1: Notes | I1: Smart License Key
A2: atharv@studiolotus.in | B2: 3ds Max | C2: Autodesk single-user | D2: License Assigned | F2: 46270 | G2: Amita Goel Team | H2: nan
A3: rajendra@studiolotus.in | B3: Adobe Acrobat | C3: Single User | D3: License Assigned | F3: 46732
A4: neelam@studiolotus.in | B4: Adobe Acrobat | C4: Single User | D4: License Assigned | F4: 46732
A5: nirmal@studiolotus.in | B5: Adobe Acrobat | C5: Single User | D5: License Assigned | F5: 46732
A6: asmita.bharati@studiolotus.in | B6: Adobe Illustrator | C6: Single User | D6: License Assigned | F6: 46732
A7: neelam@studiolotus.in | B7: Adobe Illustrator | C7: Single User | D7: License Assigned | F7: 46732
A8: amrapali@studiolotus.in | B8: Adobe Illustrator | C8: Single User | D8: License Assigned | F8: 46732
A9: sm@studiolotus.in | B9: Adobe Illustrator | C9: Single User | D9: License Assigned | F9: 46732
A10: asmita.bharati@studiolotus.in | B10: Adobe InDesign | C10: Single User | D10: License Assigned | F10: 46732
A11: asmita.bharati@studiolotus.in | B11: Adobe Photoshop | C11: Single User | D11: License Assigned | F11: 46732
A12: vartika.sood@studiolotus.in | B12: Adobe Photoshop | C12: Single User | D12: License Assigned | F12: 46732
A13: prajwal@studiolotus.in | B13: Adobe Photoshop | C13: Single User | D13: License Assigned | F13: 46732
A14: rushil.jain@studiolotus.in | B14: Adobe Photoshop | C14: Single User | D14: License Assigned | F14: 46732
... A114: yatin.tokas@studiolotus.in | B114: AutoCAD LT | C114: Single User | D114: License Assigned | F114: 46378
A115: unassigned-autocad-dec26-1@studiolotus.in | B115: AutoCAD LT | C115: Single User | D115: Available | F115: 46378 | H115: New licence - assign to user
A116: unassigned-autocad-dec26-2@studiolotus.in | B116: AutoCAD LT | C116: Single User | D116: Available | F116: 46378 | H116: New licence - assign to user
A117: unassigned-autocad-dec26-3@studiolotus.in | B117: AutoCAD LT | C117: Single User | D117: Available | F117: 46378 | H117: New licence - assign to user
A118: unassigned-autocad-dec26-4@studiolotus.in | B118: AutoCAD LT | C118: Single User | D118: Available | F118: 46378 | H118: New licence - assign to user
A119: unassigned-autocad-dec26-5@studiolotus.in | B119: AutoCAD LT | C119: Single User | D119: Available | F119: 46378 | H119: New licence - assign to user
A120: unassigned-autocad-dec26-6@studiolotus.in | B120: AutoCAD LT | C120: Single User | D120: Available | F120: 46378 | H120: New licence - assign to user
A121: atharv@studiolotus.in | B121: Corona | C121: Single User | D121: License Assigned | F121: 46213
A122: anshika@studiolotus.in | B122: Enscape | C122: Single User | D122: License Assigned | F122: 46471
A123: nikita.bhatia@studiolotus.in | B123: Enscape | C123: Single User | D123: License Assigned | F123: 46471
A124: isha.agrawal@studiolotus.in | B124: Enscape | C124: Single User | D124: License Assigned | F124: 46471
A125: siya.suri@studiolotus.in | B125: Enscape | C125: Single User | D125: License Assigned | F125: 46471
A126: reetika.singh@studiolotus.in | B126: Enscape | C126: Single User | D126: License Assigned | F126: 46415
A127: krishna.mandviwala@studiolotus.in | B127: Enscape | C127: Single User | D127: License Assigned | F127: 46435
A128: amita@studiolotus.in | B128: Microsoft 365 Business Standard | C128: Single User | D128: License Assigned | F128: 46357 | H128: UPN: amita@tacdesign.onmicrosoft.com
A129: devdutt.kumar@studiolotus.in | B129: Microsoft 365 Business Standard | C129: Single User | D129: License Assigned | F129: 46357 | H129: UPN: dev@tacdesign.onmicrosoft.com
A130: prashant.bharadwaj@studiolotus.in | B130: Microsoft 365 Business Standard | C130: Single User | D130: License Assigned | F130: 46357 | H130: UPN: prashant@tacdesign.onmicrosoft.com
A131: rajendra@studiolotus.in | B131: Microsoft 365 Business Standard | C131: Single User | D131: License Assigned | F131: 46357 | H131: UPN: rajendra@tacdesign.onmicrosoft.com
A132: tanvi@studiolotus.in | B132: Microsoft 365 Business Standard | C132: Single User | D132: License Assigned | F132: 46357 | H132: UPN: tanvi@tacdesign.onmicrosoft.com
A133: asha@studiolotus.in | B133: Microsoft 365 Business Standard | C133: Single User | D133: License Assigned | F133: 46357 | H133: UPN: asha@tacdesign.onmicrosoft.com
A134: asmita.bharati@studiolotus.in | B134: Microsoft 365 Business Standard | C134: Single User | D134: License Assigned | F134: 46357 | H134: UPN: bdteam@tacdesign.onmicrosoft.com
B135: Microsoft 365 Business Standard | C135: Single User | D135: License Assigned | F135: 46357 | H135: UPN: lap05@tacdesign.onmicrosoft.com
A136: neelam@studiolotus.in | B136: Microsoft 365 Business Standard | C136: Single User | D136: License Assigned | F136: 46357 | H136: UPN: neelam@tacdesign.onmicrosoft.com
A137: varun.srivastava@studiolotus.in | B137: Microsoft 365 Business Standard | C137: Single User | D137: License Assigned | F137: 46357 | H137: UPN: varun@tacdesign.onmicrosoft.com
A138: aditi.agashe@studiolotus.in | B138: Microsoft 365 Business Standard (no teams) | C138: Single User | D138: License Assigned | F138: 46357 | H138: UPN: lds38@tacdesign.onmicrosoft.com
A139: aditi.panwar@studiolotus.in | B139: Microsoft 365 Business Standard (no teams) | C139: Single User | D139: License Assigned | F139: 46357 | H139: UPN: lds20@tacdesign.onmicrosoft.com
...

Sheet Groups
A1: Group Key | B1: Group / Team | C1: Principal | D1: Team Lead | E1: Parent | F1: Color Hex | G1: Sort | H1: Active | I1: Notes
A2: HARSH-FINANCE | B2: Finance & Accounts | C2: Harsh Vardhan | D2: Rajendra Kumar Mohanty | E2: Harsh Vardhan | F2: #E3EEF4 | G2: 10 | H2: =TRUE() -> TRUE | I2: Function-wise rollup for Harsh Vardhan.
A3: HARSH-PEOPLE | B3: People & Culture | C3: Harsh Vardhan | D3: Isha Singh | E3: Harsh Vardhan | F3: #F5E2EA | G3: 20 | H3: =TRUE() -> TRUE | I3: Function-wise rollup for Harsh Vardhan.
A4: HARSH-BD | B4: BD & Comms | C4: Harsh Vardhan | D4: Amita Goel | E4: Harsh Vardhan | F4: #E3F1E7 | G4: 30 | H4: =TRUE() -> TRUE | I4: Function-wise rollup for Harsh Vardhan.
A5: HARSH-IT | B5: IT & Tech | C5: Harsh Vardhan | D5: Devdutt Kumar | E5: Harsh Vardhan | F5: #E7F0D8 | G5: 40 | H5: =TRUE() -> TRUE | I5: Function-wise rollup for Harsh Vardhan.
A6: HARSH-ADMIN | B6: Admin & Infra | C6: Harsh Vardhan | D6: Kavita Chatola | E6: Harsh Vardhan | F6: #ECE6F7 | G6: 50 | H6: =TRUE() -> TRUE | I6: Function-wise rollup for Harsh Vardhan.
A7: HARSH-HOMES | B7: Homes | C7: Harsh Vardhan | D7: Harsh Vardhan | E7: Harsh Vardhan | F7: #E2EEF7 | G7: 60 | H7: =TRUE() -> TRUE | I7: Function-wise rollup for Harsh Vardhan.
A8: AMB-DIRECT | B8: Direct Reports | C8: Ambrish Arora | D8: Ambrish Arora | E8: Ambrish Arora | F8: #DCEFF0 | G8: 70 | H8: =TRUE() -> TRUE
A9: AMB-PRAJWAL | B9: Prajwal Yashwant Amin Team | C9: Ambrish Arora | D9: Prajwal Yashwant Amin | E9: Ambrish Arora | F9: #F7EFC9 | G9: 80 | H9: =TRUE() -> TRUE
A10: AMB-VARUN | B10: Varun Srivastava Team | C10: Ambrish Arora | D10: Varun Srivastava | E10: Ambrish Arora | F10: #E7E8F6 | G10: 100 | H10: =TRUE() -> TRUE
A11: AMB-YATIN | B11: Yatin Tokas Team | C11: Ambrish Arora | D11: Yatin Tokas | E11: Ambrish Arora | F11: #E0F4EF | G11: 110 | H11: =TRUE() -> TRUE | I11: Karthick R is grouped here as requested.
A12: ANKUR-DIRECT | B12: Direct Reports | C12: Ankur Choksi | D12: Ankur Choksi | E12: Ankur Choksi | F12: #F3E3D8 | G12: 120 | H12: =TRUE() -> TRUE
A13: ANKUR-PRASHANT | B13: Prashant Bharadwaj Team | C13: Ankur Choksi | D13: Prashant Bharadwaj | E13: Ankur Choksi | F13: #DDE7F7 | G13: 130 | H13: =TRUE() -> TRUE
A14: ANKUR-SWATI | B14: Swati Seshadri Team | C14: Ankur Choksi | D14: Swati Seshadri | E14: Ankur Choksi | F14: #F1E4F6 | G14: 140 | H14: =TRUE() -> TRUE
A15: ASHA-DIRECT | B15: Direct Reports | C15: Asha Sairam | D15: Asha Sairam | E15: Asha Sairam | F15: #EAF0DC | G15: 150 | H15: =TRUE() -> TRUE
A16: ASHA-INSIYA | B16: Insiya Pithawala Team | C16: Asha Sairam | D16: Insiya Pithawala | E16: Asha Sairam | F16: #F7DDD9 | G16: 160 | H16: =TRUE() -> TRUE
A17: ASHA-NEELAM | B17: Neelam Das Team | C17: Asha Sairam | D17: Neelam Das | E17: Asha Sairam | F17: #DFF1F6 | G17: 170 | H17: =TRUE() -> TRUE | I17: Neelam reports to Asha; not a principal node.
A18: ASHA-RANDHIR | B18: Randhir Kumar Team | C18: Asha Sairam | D18: Randhir Kumar | E18: Asha Sairam | F18: #F6EFD8 | G18: 180 | H18: =TRUE() -> TRUE

Sheet License_Inventory
A1: Contract Key | B1: Entity | C1: Software | D1: Category | E1: Contract No | F1: Contract Type | G1: Serial No | H1: People | I1: Start Date | J1: End Date | K1: User Type | L1: Status | M1: Vendor | N1: Contact Email | O1: Days to Expiry | P1: Renewal Status | Q1: License Assigned | R1: Spare Licenses | S1: Utilisation % | T1: Notes | U1: Smart License Key
A2: INV-001 | B2: TAC Design (Studio Lotus) | C2: AutoCAD LT | D2: Design Software | E2: 110005089936 | F2: Subscription | G2: 575-47375883 | H2: 25 | I2: 45970 | J2: 46335 | K2: Single User | L2: Active | M2: CAPRICOT | N2: itsupport@studiolotus.in | O2: =IF(J2="","",J2-TODAY()) -> 160 | P2: =IF(J2="","No End Date",IF(J2-TODAY()<0,"Expired",IF(J2-TODAY()<=30,"Expiring Soon",IF(J2-TODAY()<=90,"Watch","Active")))) -> Active | Q2: 83 | R2: 0 | S2: =IFERROR(IF(H2=0,"",COUNTIF(Licenses!$B:$B,C2)/H2),"") -> 3.68 | U2: AUTOCAD LT
A3: INV-002 | B3: TAC Design (Studio Lotus) | C3: AutoCAD LT | D3: Design Software | E3: 110003617657 | F3: Subscription | G3: 572-11051743 | H3: 10 | I3: 45830 | J3: 46195 | K3: Single User | L3: Active | M3: CAPRICOT | N3: itsupport@studiolotus.in | O3: =IF(J3="","",J3-TODAY()) -> 20 | P3: =IF(J3="","No End Date",IF(J3-TODAY()<0,"Expired",IF(J3-TODAY()<=30,"Expiring Soon",IF(J3-TODAY()<=90,"Watch","Active")))) -> Expiring Soon | Q3: 83 | R3: 0 | S3: =IFERROR(IF(H3=0,"",COUNTIF(Licenses!$B:$B,C3)/H3),"") -> 9.2 | U3: AUTOCAD LT
A4: INV-003 | B4: TAC Design (Studio Lotus) | C4: AutoCAD LT | D4: Design Software | E4: 110004469439 | F4: Subscription | G4: 574-14236158 | H4: 10 | I4: 45864 | J4: 46229 | K4: Single User | L4: Active | M4: MICROGENESIS | N4: itsupport@studiolotus.in | O4: =IF(J4="","",J4-TODAY()) -> 54 | P4: =IF(J4="","No End Date",IF(J4-TODAY()<0,"Expired",IF(J4-TODAY()<=30,"Expiring Soon",IF(J4-TODAY()<=90,"Watch","Active")))) -> Watch | Q4: 83 | R4: 0 | S4: =IFERROR(IF(H4=0,"",COUNTIF(Licenses!$B:$B,C4)/H4),"") -> 9.2 | U4: AUTOCAD LT
A5: INV-004 | B5: TAC Design (Studio Lotus) | C5: AutoCAD LT | D5: Design Software | E5: 110003696736 | F5: Subscription | G5: 572-44150915 | H5: 10 | I5: 45898 | J5: 46263 | K5: Single User | L5: Active | M5: CAPRICOT | N5: itsupport@studiolotus.in | O5: =IF(J5="","",J5-TODAY()) -> 88 | P5: =IF(J5="","No End Date",IF(J5-TODAY()<0,"Expired",IF(J5-TODAY()<=30,"Expiring Soon",IF(J5-TODAY()<=90,"Watch","Active")))) -> Watch | Q5: 83 | R5: 0 | S5: =IFERROR(IF(H5=0,"",COUNTIF(Licenses!$B:$B,C5)/H5),"") -> 9.2 | U5: AUTOCAD LT
A6: INV-005 | B6: TAC Design (Studio Lotus) | C6: AutoCAD LT | D6: Design Software | E6: 110004850159 | F6: Subscription | G6: 575-01328894 | H6: 20 | I6: 45898 | J6: 46263 | K6: Single User | L6: Active | M6: MICROGENESIS | N6: itsupport@studiolotus.in | O6: =IF(J6="","",J6-TODAY()) -> 88 | P6: =IF(J6="","No End Date",IF(J6-TODAY()<0,"Expired",IF(J6-TODAY()<=30,"Expiring Soon",IF(J6-TODAY()<=90,"Watch","Active")))) -> Watch | Q6: 83 | R6: 0 | S6: =IFERROR(IF(H6=0,"",COUNTIF(Licenses!$B:$B,C6)/H6),"") -> 4.6 | U6: AUTOCAD LT
A7: INV-006 | B7: TAC Design (Studio Lotus) | C7: AutoCAD LT | D7: Design Software | E7: 110004850190 | F7: Subscription | G7: 575-01327213 | H7: 10 | I7: 45898 | J7: 46263 | K7: Single User | L7: Active | M7: KRION COUSULTUING | N7: itsupport@studiolotus.in | O7: =IF(J7="","",J7-TODAY()) -> 88 | P7: =IF(J7="","No End Date",IF(J7-TODAY()<0,"Expired",IF(J7-TODAY()<=30,"Expiring Soon",IF(J7-TODAY()<=90,"Watch","Active")))) -> Watch | Q7: 83 | R7: 0 | S7: =IFERROR(IF(H7=0,"",COUNTIF(Licenses!$B:$B,C7)/H7),"") -> 9.2 | U7: AUTOCAD LT
A8: INV-007 | B8: TAC Design (Studio Lotus) | C8: 3DS MAX | D8: Design Software | E8: 110004508222 | F8: Subscription | G8: 574-21740988 | H8: 1 | I8: 45905 | J8: 46270 | K8: Single User | L8: Active | M8: MICROGENESIS | N8: itsupport@studiolotus.in | O8: =IF(J8="","",J8-TODAY()) -> 95 | P8: =IF(J8="","No End Date",IF(J8-TODAY()<0,"Expired",IF(J8-TODAY()<=30,"Expiring Soon",IF(J8-TODAY()<=90,"Watch","Active")))) -> Active | Q8: 1 | R8: 0 | S8: =IFERROR(IF(H8=0,"",COUNTIF(Licenses!$B:$B,C8)/H8),"") -> 1 | U8: 3DS MAX
A9: INV-008 | B9: Mangrove Collective | C9: AutoCAD LT | D9: Design Software | E9: 110003640750 | F9: Subscription | G9: 572-20019986 | H9: 6 | I9: 44386 | K9: Single User | L9: Active | O9: =IF(J9="","",J9-TODAY()) | P9: =IF(J9="","No End Date",IF(J9-TODAY()<0,"Expired",IF(J9-TODAY()<=30,"Expiring Soon",IF(J9-TODAY()<=90,"Watch","Active")))) -> No End Date | Q9: 83 | R9: 0 | S9: =IFERROR(IF(H9=0,"",COUNTIF(Licenses!$B:$B,C9)/H9),"") -> 15.333333 | U9: AUTOCAD LT
A10: INV-009 | B10: Mangrove Collective | C10: AutoCAD LT | D10: Design Software | E10: 110003651805 | F10: Subscription | G10: 572-26485532 | H10: 7 | I10: 44395 | K10: Single User | L10: Active | O10: =IF(J10="","",J10-TODAY()) | P10: =IF(J10="","No End Date",IF(J10-TODAY()<0,"Expired",IF(J10-TODAY()<=30,"Expiring Soon",IF(J10-TODAY()<=90,"Watch","Active")))) -> No End Date | Q10: 83 | R10: 0 | S10: =IFERROR(IF(H10=0,"",COUNTIF(Licenses!$B:$B,C10)/H10),"") -> 13.142857 | U10: AUTOCAD LT
A11: INV-010 | B11: Studio Lotus (Personal) | C11: AutoCAD LT | D11: Design Software | E11: 110003484290 | F11: Subscription | H11: 1 | I11: 44630 | K11: Single User | L11: Active | O11: =IF(J11="","",J11-TODAY()) | P11: =IF(J11="","No End Date",IF(J11-TODAY()<0,"Expired",IF(J11-TODAY()<=30,"Expiring Soon",IF(J11-TODAY()<=90,"Watch","Active")))) -> No End Date | Q11: 83 | R11: 0 | S11: =IFERROR(IF(H11=0,"",COUNTIF(Licenses!$B:$B,C11)/H11),"") -> 92 | U11: AUTOCAD LT
A12: INV-011 | B12: TAC Design (Studio Lotus) | C12: ADOBE PHOTOSHOP CC | D12: Adobe Creative | F12: Subscription | H12: 20 | I12: 45674 | J12: 46732 | K12: SINGLE USER | L12: Active | M12: MICROGENESIS | N12: nirmal@studiolotus.in | O12: =IF(J12="","",J12-TODAY()) -> 557 | P12: =IF(J12="","No End Date",IF(J12-TODAY()<0,"Expired",IF(J12-TODAY()<=30,"Expiring Soon",IF(J12-TODAY()<=90,"Watch","Active")))) -> Active | Q12: 0 | R12: 20 | S12: =IFERROR(IF(H12=0,"",COUNTIF(Licenses!$B:$B,C12)/H12),"") -> 0 | U12: ADOBE PHOTOSHOP
A13: INV-012 | B13: TAC Design (Studio Lotus) | C13: ADOBE INDESIGN | D13: Adobe Creative | F13: Subscription | H13: 2 | I13: 45674 | J13: 46732 | K13: SINGLE USER | L13: Active | M13: MICROGENESIS | N13: nirmal@studiolotus.in | O13: =IF(J13="","",J13-TODAY()) -> 557 | P13: =IF(J13="","No End Date",IF(J13-TODAY()<0,"Expired",IF(J13-TODAY()<=30,"Expiring Soon",IF(J13-TODAY()<=90,"Watch","Active")))) -> Active | Q13: 2 | R13: 0 | S13: =IFERROR(IF(H13=0,"",COUNTIF(Licenses!$B:$B,C13)/H13),"") -> 0.5 | U13: ADOBE INDESIGN
A14: INV-013 | B14: TAC Design (Studio Lotus) | C14: ADOBE ILLUSTRATOR | D14: Adobe Creative | F14: Subscription | H14: 4 | I14: 45674 | J14: 46732 | K14: SINGLE USER | L14: Active | M14: MICROGENESIS | N14: nirmal@studiolotus.in | O14: =IF(J14="","",J14-TODAY()) -> 557 | P14: =IF(J14="","No End Date",IF(J14-TODAY()<0,"Expired",IF(J14-TODAY()<=30,"Expiring Soon",IF(J14-TODAY()<=90,"Watch","Active")))) -> Active | Q14: 4 | R14: 0 | S14: =IFERROR(IF(H14=0,"",COUNTIF(Licenses!$B:$B,C14)/H14),"") -> 1 | U14: ADOBE ILLUSTRATOR
A15: INV-014 | B15: TAC Design (Studio Lotus) | C15: ADOBE ACROBAT | D15: Adobe Creative | F15: Subscription | H15: 3 | I15: 45674 | J15: 46732 | K15: SINGLE USER | L15: Active | M15: MICROGENESIS | N15: nirmal@studiolotus.in | O15: =IF(J15="","",J15-TODAY()) -> 557 | P15: =IF(J15="","No End Date",IF(J15-TODAY()<0,"Expired",IF(J15-TODAY()<=30,"Expiring Soon",IF(J15-TODAY()<=90,"Watch","Active")))) -> Active | Q15: 3 | R15: 0 | S15: =IFERROR(IF(H15=0,"",COUNTIF(Licenses!$B:$B,C15)/H15),"") -> 1 | U15: ADOBE ACROBAT
A16: INV-015 | B16: TAC Design (Studio Lotus) | C16: Microsoft 365 Business Standard | D16: Productivity | F16: Subscription | H16: 10 | I16: 45992 | J16: 46357 | K16: SINGLE USER | L16: Active | M16: ADROIT | O16: =IF(J16="","",J16-TODAY()) -> 182 | P16: =IF(J16="","No End Date",IF(J16-TODAY()<0,"Expired",IF(J16-TODAY()<=30,"Expiring Soon",IF(J16-TODAY()<=90,"Watch","Active")))) -> Active | Q16: 0 | R16: 87 | S16: =IFERROR(IF(H16=0,"",COUNTIF(Licenses!$B:$B,C16)/H16),"") -> 1 | U16: MS OFFICE 365 APPS
A17: INV-016 | B17: TAC Design (Studio Lotus) | C17: Microsoft 365 Business Standard (no teams) | D17: Productivity | F17: Subscription | H17: 95 | I17: 45992 | J17: 46357 | K17: SINGLE USER | L17: Active | M17: ADROIT | O17: =IF(J17="","",J17-TODAY()) -> 182 | P17: =IF(J17="","No End Date",IF(J17-TODAY()<0,"Expired",IF(J17-TODAY()<=30,"Expiring Soon",IF(J17-TODAY()<=90,"Watch","Active")))) -> Active | Q17: 0 | R17: 31 | S17: =IFERROR(IF(H17=0,"",COUNTIF(Licenses!$B:$B,C17)/H17),"") -> 0.33684211 | U17: MS OFFICE 365 STANDARD
A18: INV-018 | B18: TAC Design (Studio Lotus) | C18: SKETCHUP PRO | D18: Design Software | F18: Subscription | H18: 19 | I18: 45813 | J18: 46178 | K18: SINGLE USER | L18: Active | M18: MICROGENESIS | O18: =IF(J18="","",J18-TODAY()) -> 3 | P18: =IF(J18="","No End Date",IF(J18-TODAY()<0,"Expired",IF(J18-TODAY()<=30,"Expiring Soon",IF(J18-TODAY()<=90,"Watch","Active")))) -> Expiring Soon | Q18: 0 | R18: 19 | S18: =IFERROR(IF(H18=0,"",COUNTIF(Licenses!$B:$B,C18)/H18),"") -> 2.5789474 | U18: SKETCHUP PRO
A19: INV-019 | B19: TAC Design (Studio Lotus) | C19: SKETCHUP PRO | D19: Design Software | F19: Subscription | H19: 12 | I19: 45890 | J19: 46255 | K19: SINGLE USER | L19: Active | M19: MICROGENESIS | O19: =IF(J19="","",J19-TODAY()) -> 80 | P19: =IF(J19="","No End Date",IF(J19-TODAY()<0,"Expired",IF(J19-TODAY()<=30,"Expiring Soon",IF(J19-TODAY()<=90,"Watch","Active")))) -> Watch | Q19: 0 | R19: 12 | S19: =IFERROR(IF(H19=0,"",COUNTIF(Licenses!$B:$B,C19)/H19),"") -> 4.0833333 | U19: SKETCHUP PRO
A20: INV-020 | B20: TAC Design (Studio Lotus) | C20: SKETCHUP PRO | D20: Design Software | F20: Subscription | H20: 3 | I20: 45915 | J20: 46280 | K20: SINGLE USER | L20: Active | M20: MICROGENESIS | O20: =IF(J20="","",J20-TODAY()) -> 105 | P20: =IF(J20="","No End Date",IF(J20-TODAY()<0,"Expired",IF(J20-TODAY()<=30,"Expiring Soon",IF(J20-TODAY()<=90,"Watch","Active")))) -> Active | Q20: 0 | R20: 3 | S20: =IFERROR(IF(H20=0,"",COUNTIF(Licenses!$B:$B,C20)/H20),"") -> 16.333333 | U20: SKETCHUP PRO
A21: INV-021 | B21: TAC Design (Studio Lotus) | C21: SKETCHUP PRO | D21: Design Software | F21: Subscription | H21: 6 | I21: 45926 | J21: 46291 | K21: SINGLE USER | L21: Active | M21: MICROGENESIS | O21: =IF(J21="","",J21-TODAY()) -> 116 | P21: =IF(J21="","No End Date",IF(J21-TODAY()<0,"Expired",IF(J21-TODAY()<=30,"Expiring Soon",IF(J21-TODAY()<=90,"Watch","Active")))) -> Active | Q21: 0 | R21: 6 | S21: =IFERROR(IF(H21=0,"",COUNTIF(Licenses!$B:$B,C21)/H21),"") -> 8.1666667 | U21: SKETCHUP PRO
A22: INV-022 | B22: TAC Design (Studio Lotus) | C22: SKETCHUP PRO | D22: Design Software | F22: Subscription | H22: 5 | I22: 45957 | J22: 46322 | K22: SINGLE USER | L22: Active | M22: MICROGENESIS | O22: =IF(J22="","",J22-TODAY()) -> 147 | P22: =IF(J22="","No End Date",IF(J22-TODAY()<0,"Expired",IF(J22-TODAY()<=30,"Expiring Soon",IF(J22-TODAY()<=90,"Watch","Active")))) -> Active | Q22: 0 | R22: 5 | S22: =IFERROR(IF(H22=0,"",COUNTIF(Licenses!$B:$B,C22)/H22),"") -> 9.8 | U22: SKETCHUP PRO
A23: INV-023 | B23: TAC Design (Studio Lotus) | C23: SKETCHUP PRO | D23: Design Software | F23: Subscription | H23: 4 | I23: 46008 | J23: 46373 | K23: SINGLE USER | L23: Active | M23: MICROGENESIS | O23: =IF(J23="","",J23-TODAY()) -> 198 | P23: =IF(J23="","No End Date",IF(J23-TODAY()<0,"Expired",IF(J23-TODAY()<=30,"Expiring Soon",IF(J23-TODAY()<=90,"Watch","Active")))) -> Active | Q23: 0 | R23: 4 | S23: =IFERROR(IF(H23=0,"",COUNTIF(Licenses!$B:$B,C23)/H23),"") -> 12.25 | U23: SKETCHUP PRO
A24: INV-024 | B24: TAC Design (Studio Lotus) | C24: SKETCHUP PRO | D24: Design Software | F24: Subscription | H24: 1 | I24: 46009 | J24: 46374 | K24: SINGLE USER | L24: Active | M24: MICROGENESIS | O24: =IF(J24="","",J24-TODAY()) -> 199 | P24: =IF(J24="","No End Date",IF(J24-TODAY()<0,"Expired",IF(J24-TODAY()<=30,"Expiring Soon",IF(J24-TODAY()<=90,"Watch","Active")))) -> Active | Q24: 0 | R24: 1 | S24: =IFERROR(IF(H24=0,"",COUNTIF(Licenses!$B:$B,C24)/H24),"") -> 49 | U24: SKETCHUP PRO
A25: INV-025 | B25: TAC Design (Studio Lotus) | C25: ENSCAPE | D25: Visualization | F25: Subscription | H25: 4 | I25: 46106 | J25: 46471 | K25: SINGLE USER | L25: Active | M25: MICROGENESIS | O25: =IF(J25="","",J25-TODAY()) -> 296 | P25: =IF(J25="","No End Date",IF(J25-TODAY()<0,"Expired",IF(J25-TODAY()<=30,"Expiring Soon",IF(J25-TODAY()<=90,"Watch","Active")))) -> Active | Q25: 0 | R25: 4 | S25: =IFERROR(IF(H25=0,"",COUNTIF(Licenses!$B:$B,C25)/H25),"") -> 1.5 | U25: ENSCAPE
A26: INV-026 | B26: TAC Design (Studio Lotus) | C26: ENSCAPE | D26: Visualization | F26: Subscription | H26: 1 | I26: 46050 | J26: 46415 | K26: SINGLE USER | L26: Active | M26: MICROGENESIS | O26: =IF(J26="","",J26-TODAY()) -> 240 | P26: =IF(J26="","No End Date",IF(J26-TODAY()<0,"Expired",IF(J26-TODAY()<=30,"Expiring Soon",IF(J26-TODAY()<=90,"Watch","Active")))) -> Active | Q26: 0 | R26: 1 | S26: =IFERROR(IF(H26=0,"",COUNTIF(Licenses!$B:$B,C26)/H26),"") -> 6 | U26: ENSCAPE
A27: INV-027 | B27: TAC Design (Studio Lotus) | C27: ENSCAPE | D27: Visualization | F27: Subscription | H27: 1 | I27: 46070 | J27: 46435 | K27: SINGLE USER | L27: Active | M27: MICROGENESIS | O27: =IF(J27="","",J27-TODAY()) -> 260 | P27: =IF(J27="","No End Date",IF(J27-TODAY()<0,"Expired",IF(J27-TODAY()<=30,"Expiring Soon",IF(J27-TODAY()<=90,"Watch","Active")))) -> Active | Q27: 0 | R27: 1 | S27: =IFERROR(IF(H27=0,"",COUNTIF(Licenses!$B:$B,C27)/H27),"") -> 6 | U27: ENSCAPE
A28: INV-028 | B28: TAC Design (Studio Lotus) | C28: CORONA | D28: Visualization | F28: Subscription | H28: 1 | I28: 45848 | J28: 46213 | K28: SINGLE USER | L28: Active | M28: MICROGENESIS | O28: =IF(J28="","",J28-TODAY()) -> 38 | P28: =IF(J28="","No End Date",IF(J28-TODAY()<0,"Expired",IF(J28-TODAY()<=30,"Expiring Soon",IF(J28-TODAY()<=90,"Watch","Active")))) -> Watch | Q28: 0 | R28: 1 | S28: =IFERROR(IF(H28=0,"",COUNTIF(Licenses!$B:$B,C28)/H28),"") -> 1 | U28: CORONA
A29: INV-029 | B29: TAC Design (Studio Lotus) | C29: AutoCAD LT | D29: Design Software | F29: Subscription | H29: 6 | I29: 46013 | J29: 46378 | K29: Single User | L29: Active | M29: CAPRICOT | N29: itsupport@studiolotus.in | O29: =IF(J29="","",J29-TODAY()) -> 203 | P29: =IF(J29="","No End Date",IF(J29-TODAY()<0,"Expired",IF(J29-TODAY()<=30,"Expiring Soon",IF(J29-TODAY()<=90,"Watch","Active")))) -> Active | Q29: 0 | R29: 6 | S29: =IFERROR(IF(H29=0,"",COUNTIF(Licenses!$B:$B,C29)/H29),"") -> 15.333333 | T29: 6 new licences - Dec 22 2026 expiry | U29: AUTOCAD LT

Sheet User_License_Matrix
A1: Who has what — User × License matrix
A2: ✓ marks every (user, tool) pair from the Licenses sheet. Auto-refreshes on every edit. Last: 6/1/2026, 11:00:05 AM
A4: Employee | B4: Email | C4: Principal | D4: Team | E4: Job Title | F4: AutoCAD LT | G4: SketchUp Pro | H4: Microsoft 365 Business Standard (no teams) | I4: Adobe Photoshop | J4: Microsoft 365 Business Standard | K4: Enscape | L4: Adobe Illustrator | M4: Adobe Acrobat | N4: 3ds Max | O4: Adobe InDesign | P4: Corona | Q4: Total
A5: Ambrish Arora | B5: ambrish@studiolotus.in | C5: Ambrish Arora | D5: Direct Reports | E5: Principal | Q5: 0
A6: Aditi Panwar | B6: aditi.panwar@studiolotus.in | C6: Ambrish Arora | D6: Prajwal Yashwant Amin Team | E6: Architect | F6: ✓ | G6: ✓ | H6: ✓ | Q6: 3
A7: Ayushi Patwari | B7: ayushi.patwari@studiolotus.in | C7: Ambrish Arora | D7: Prajwal Yashwant Amin Team | E7: Architect | F7: ✓ | G7: ✓ | H7: ✓ | Q7: 3
A8: Prajwal Yashwant Amin | B8: prajwal@studiolotus.in | C8: Ambrish Arora | D8: Prajwal Yashwant Amin Team | E8: Project Architect | F8: ✓ | G8: ✓ | H8: ✓ | I8: ✓ | Q8: 4
A9: Puru Bhatia | B9: puru.bhatia@studiolotus.in | C9: Ambrish Arora | D9: Prajwal Yashwant Amin Team | E9: Architect | F9: ✓ | G9: ✓ | Q9: 2
A10: Suhani Khandelwal | B10: suhani.khandelwal@studiolotus.in | C10: Ambrish Arora | D10: Prajwal Yashwant Amin Team | E10: Architect | F10: ✓ | G10: ✓ | H10: ✓ | Q10: 3
A11: Adhiraj Sirkeck | B11: adhiraj.sirkeck@studiolotus.in | C11: Ambrish Arora | D11: Varun Srivastava Team | E11: Sr. Architect | F11: ✓ | G11: ✓ | Q11: 2
A12: Harsha Singh | B12: harsha.singh@studiolotus.in | C12: Ambrish Arora | D12: Varun Srivastava Team | E12: Architect | F12: ✓ | H12: ✓ | Q12: 2
A13: Khushboo Pandey | B13: khushboo.pandey@studiolotus.in | C13: Ambrish Arora | D13: Varun Srivastava Team | E13: Project Architect | F13: ✓ | Q13: 1
A14: Nikita Bhatia | B14: nikita.bhatia@studiolotus.in | C14: Ambrish Arora | D14: Varun Srivastava Team | E14: Project Architect | F14: ✓ | K14: ✓ | Q14: 2
A15: Rida Drabu | B15: rida@studiolotus.in | C15: Ambrish Arora | D15: Varun Srivastava Team | E15: Architect | F15: ✓ | G15: ✓ | Q15: 2
A16: Rushil Jain | B16: rushil.jain@studiolotus.in | C16: Ambrish Arora | D16: Varun Srivastava Team | E16: Architect | F16: ✓ | G16: ✓ | I16: ✓ | Q16: 3
A17: Satwik Singh Rathour | B17: satwik@studiolotus.in | C17: Ambrish Arora | D17: Varun Srivastava Team | E17: Sr. Architect | F17: ✓ | G17: ✓ | H17: ✓ | Q17: 3
A18: Varun Srivastava | B18: varun.srivastava@studiolotus.in | C18: Ambrish Arora | D18: Varun Srivastava Team | E18: Group Leader | F18: ✓ | G18: ✓ | J18: ✓ | Q18: 3
A19: Vivin Neelankavil | B19: vivin@studiolotus.in | C19: Ambrish Arora | D19: Varun Srivastava Team | E19: Sr. Architect | F19: ✓ | G19: ✓ | H19: ✓ | Q19: 3
A20: Abiyah Grace Ebby | B20: abiyah.grace@studiolotus.in | C20: Ambrish Arora | D20: Yatin Tokas Team | E20: Architect | F20: ✓ | Q20: 1
A21: Deepak Chakicherla | B21: deepak.chakicherla@studiolotus.in | C21: Ambrish Arora | D21: Yatin Tokas Team | E21: Architect | F21: ✓ | G21: ✓ | H21: ✓ | Q21: 3
A22: Jagdish Samal | B22: jagdish.samal@studiolotus.in | C22: Ambrish Arora | D22: Yatin Tokas Team | E22: Architect | F22: ✓ | Q22: 1
A23: Karthick R | B23: karthick.r@studiolotus.in | C23: Ambrish Arora | D23: Yatin Tokas Team | E23: Sr. Architect | F23: ✓ | G23: ✓ | Q23: 2
A24: Kashish Singh | B24: kashish.singh@studiolotus.in | C24: Ambrish Arora | D24: Yatin Tokas Team | E24: Architect | F24: ✓ | Q24: 1
A25: Mihir Jagdishbhai Ramani | B25: mihir.ramani@studiolotus.in | C25: Ambrish Arora | D25: Yatin Tokas Team | E25: Architect | F25: ✓ | G25: ✓ | Q25: 2
A26: Priyanka Jawa | B26: priyanka.jawa@studiolotus.in | C26: Ambrish Arora | D26: Yatin Tokas Team | E26: Sr. Architect | F26: ✓ | G26: ✓ | H26: ✓ | Q26: 3
A27: Vipul Sharma | B27: vipulsh1402@gmail.com | C27: Ambrish Arora | D27: Yatin Tokas Team | E27: Intern | Q27: 0
A28: Vishal Dubey | B28: vishal.dubey@studiolotus.in | C28: Ambrish Arora | D28: Yatin Tokas Team | E28: Project Architect | F28: ✓ | Q28: 1
A29: Yatin Tokas | B29: yatin.tokas@studiolotus.in | C29: Ambrish Arora | D29: Yatin Tokas Team | E29: Project Lead | F29: ✓ | G29: ✓ | H29: ✓ | Q29: 3
A30: Ankur Choksi | B30: ankur@lotuslink.in | C30: Ankur Choksi | D30: Direct Reports | E30: Principal | Q30: 0
A31: Aditi Sudheer Kari | B31: aditi3641arch22@spa.ac.in | C31: Ankur Choksi | D31: Prashant Bharadwaj Team | E31: Intern | Q31: 0
A32: Aditya Pandoh | B32: aditya.pandoh@studiolotus.in | C32: Ankur Choksi | D32: Prashant Bharadwaj Team | E32: Designer | F32: ✓ | G32: ✓ | H32: ✓ | Q32: 3
A33: Anisha Khandelwal | B33: anisha.khandelwal@studiolotus.in | C33: Ankur Choksi | D33: Prashant Bharadwaj Team | E33: Sr. Architect | F33: ✓ | H33: ✓ | Q33: 2
A34: Ankeeta Champatiray | B34: ankeeta@studiolotus.in | C34: Ankur Choksi | D34: Prashant Bharadwaj Team | E34: Sr. Architect | F34: ✓ | G34: ✓ | Q34: 2
A35: Deeptha Madan Gopal | B35: deeptha.mg@studiolotus.in | C35: Ankur Choksi | D35: Prashant Bharadwaj Team | E35: Architect | F35: ✓ | Q35: 1
A36: Prashant Bharadwaj | B36: prashant.bharadwaj@studiolotus.in | C36: Ankur Choksi | D36: Prashant Bharadwaj Team | E36: Associate Principal | F36: ✓ | G36: ✓ | J36: ✓ | Q36: 3
A37: Raunak Bhagat | B37: raunak.bhagat@studiolotus.in | C37: Ankur Choksi | D37: Prashant Bharadwaj Team | E37: Architect | F37: ✓ | H37: ✓ | Q37: 2
